Workbook

Sheet Datos
A1: Lote | B1: Steel | C1: Familia | D1: Destino | E1: País | G1: Financiamiento
A2: IN.1 | B2: Zincalume za | C2: ZA | D2: Valparaíso | E2: Chile | G2: LC AT Sight
A3: IN.9 | B3: Zincalume afp | C3: ZA | D3: Valparaíso | E3: Chile | G3: 210 días
A4: IN.1E | B4: Zincalume za | C4: ZA | D4: Valparaíso | E4: Chile | G4: 180 dias
A5: IN.2E | B5: Zincalume | C5: ZA | D5: Valparaíso | E5: Chile | G5: 250 días
A6: IN.7E | B6: Zincalume | C6: ZA | D6: Valparaíso | E6: Chile | G6: 120 dias
A7: CA.2 | B7: Zincalume | C7: ZA | D7: Valparaíso | E7: Chile | G7: 150 dias
A8: TU.5 | B8: Zincalume | C8: ZA | D8: Callao | E8: Perú Tupemesa | G8: 90 días
A9: CL.1 | B9: Zincalume | C9: ZA | D9: Callao | E9: Perú Calaminon
A10: IN.4 | B10: Pre-painted | C10: PPGL | D10: Valparaíso | E10: Chile
A11: IN.4E | B11: Pre-painted | C11: PPGL | D11: Valparaíso | E11: Chile
A12: IN.41E | B12: Pre-painted | C12: PPGL | D12: Valparaíso | E12: Chile
A13: TU.4 | B13: Pre-painted | C13: PPGL | D13: Callao | E13: Perú Tupemesa
A14: CL.2 | B14: Pre-painted | C14: PPGL | D14: Callao | E14: Perú Calaminon
A15: IN.10 | B15: Galvanized | C15: GI | D15: Valparaíso | E15: Chile
A16: CIN.2 | B16: Option galvanised | C16: GI | D16: Valparaíso | E16: Chile
A17: CA.1 | B17: Galvanized | C17: GI | D17: Valparaíso | E17: Chile
A18: TU.3 | B18: Galvanized | C18: GI | D18: Callao | E18: Perú Tupemesa
A19: TU.3E | B19: Galvanized AFP | C19: GI | D19: Callao | E19: Perú Tupemesa
A20: TU.6 | B20: Galvanized | C20: GI | D20: Callao | E20: Perú Tupemesa
... A53: TU.4D | B53: Pre-painted | C53: PPAM | D53: Callao | E53: Perú Tupemesa
A54: IN.4D | B54: Pre-painted | C54: PPAM | E54: Chile

Sheet PRODUCTS
E1: Complete
A2: COUNTRY | B2: LOT | C2: DESCRIPTION | D2: INQ Q'ty | E2: SUPPLIER | F2: OFFER Q'ty | G2: TYPE OF FINANCING | H2: MILL OPTION | I2: SHIPMENT | J2: PORT OF LOADING | K2: PORT OF DISCHARGE | L2: REMARK | M2: FOB USD/TON | N2: CFR USD/TON | O2: CIF USD/TON
A3: =+_xlfn.XLOOKUP(B3,Tabla22[Lote],Tabla22[País],"",0) -> Perú Tupemesa | B3: TU.7 PT | C3: PL ESTRIADA ASTM A36 2.00 X 1200 X 2400 | D3: 519.35255
A4: =+_xlfn.XLOOKUP(B4,Tabla22[Lote],Tabla22[País],"",0) -> Perú Tupemesa | B4: TU.7 PT | C4: PL ESTRIADA ASTM A36 2.50 X 1200 X 2400 | D4: 148.38644
A5: =+_xlfn.XLOOKUP(B5,Tabla22[Lote],Tabla22[País],"",0) -> Perú Tupemesa | B5: TU.7 PT | C5: PL ESTRIADA ASTM A36 2.90 X 1200 X 2400 | D5: 92.741527
A6: =+_xlfn.XLOOKUP(B6,Tabla22[Lote],Tabla22[País],"",0) -> Perú Tupemesa | B6: TU.6 PT | C6: ANG 25 x 25 x 2.5 X6M | D6: 42.058166
A7: =+_xlfn.XLOOKUP(B7,Tabla22[Lote],Tabla22[País],"",0) -> Perú Tupemesa | B7: TU.6 PT | C7: BARRA REDONDA 1/2 X 6.00 M | D7: 54.519643
A8: =+_xlfn.XLOOKUP(B8,Tabla22[Lote],Tabla22[País],"",0) -> Perú Tupemesa | B8: TU.6 PT | C8: ANG 1 1/2 x 1 1/2 x 3/32 X 6M | D8: 34.054864
A9: =+_xlfn.XLOOKUP(B9,Tabla22[Lote],Tabla22[País],"",0) -> Perú Tupemesa | B9: TU.6 PT | C9: BARRA REDONDA 5/8 X 6.00 M | D9: 67.637121
A10: =+_xlfn.XLOOKUP(B10,Tabla22[Lote],Tabla22[País],"",0) -> Perú Tupemesa | B10: TU.6 PT | C10: ANG 3/4 x 2.5 x 6M | D10: 20.212561
A11: =+_xlfn.XLOOKUP(B11,Tabla22[Lote],Tabla22[País],"",0) -> Perú Tupemesa | B11: TU.6 PT | C11: BARRA REDONDA 3/8 X 6.00 M | D11: 34.975911
A12: =+_xlfn.XLOOKUP(B12,Tabla22[Lote],Tabla22[País],"",0) -> Perú Tupemesa | B12: TU.6 PT | C12: PLATINA 1/2 X 1/8 X 6.00 M. | D12: 18.881317
A13: =+_xlfn.XLOOKUP(B13,Tabla22[Lote],Tabla22[País],"",0) -> Perú Tupemesa | B13: TU.6 PT | C13: PLATINA 2 X 1/8 X 6.00 M | D13: 23.712776
A14: =+_xlfn.XLOOKUP(B14,Tabla22[Lote],Tabla22[País],"",0) -> Perú Tupemesa | B14: TU.6 PT | C14: PLATINA 1 X 1/8 X 6.00 M. | D14: 31.441241
... A29: =+_xlfn.XLOOKUP(B29,Tabla22[Lote],Tabla22[País],"",0) -> Chile | B29: CIN.5 PT | C29: CUAD 200X200X4,00 MM 12000 | D29: 10.616916
D30: =+SUM(D3:D29) -> 1629.2894

Sheet COILS
I1: Complete
A2: COUNTRY | B2: LOT | C2: STEEL | D2: Thickness [mm] | E2: Width [mm] | F2: Used / Color / SS designation | G2: INQ Q'ty | H2: Coil weights | I2: SUPPLIER | J2: OFFER Q'ty | K2: PAYMENT TERMS | L2: COUNTRY OF ORIGIN | M2: MILL OPTION | N2: SHIPMENT | O2: PORT OF LOADING | P2: PORT OF DISCHARGE | Q2: REMARK | R2: FOB USD/TON | S2: CFR USD/TON | T2: CIF USD/TON
A3: =+_xlfn.XLOOKUP(B3,Tabla22[Lote],Tabla22[País],"",0) -> Chile | B3: CIN.2 | C3: =+_xlfn.XLOOKUP(B3,Datos!A:A,Datos!C:C,"",0) -> GI | D3: 0.81 | E3: 1220 | F3: SS40/G60 | G3: 2387.3208 | H3: 9-10 TM
A4: =+_xlfn.XLOOKUP(B4,Tabla22[Lote],Tabla22[País],"",0) -> Chile | B4: CIN.2 | C4: =+_xlfn.XLOOKUP(B4,Datos!A:A,Datos!C:C,"",0) -> GI | D4: 0.45 | E4: 1220 | F4: SS40/G40 | G4: 828.75431 | H4: 9-10 TM
A5: =+_xlfn.XLOOKUP(B5,Tabla22[Lote],Tabla22[País],"",0) -> Chile | B5: CIN.2 | C5: =+_xlfn.XLOOKUP(B5,Datos!A:A,Datos!C:C,"",0) -> GI | D5: 0.95 | E5: 1220 | F5: SS40/G60 | G5: 83.660549 | H5: 9-10 TM
A6: =+_xlfn.XLOOKUP(B6,Tabla22[Lote],Tabla22[País],"",0) -> Chile | B6: CIN.2 | C6: =+_xlfn.XLOOKUP(B6,Datos!A:A,Datos!C:C,"",0) -> GI | D6: 1.5 | E6: 1220 | F6: SS40/G60 | G6: 190.92184 | H6: 9-10 TM
A7: =+_xlfn.XLOOKUP(B7,Tabla22[Lote],Tabla22[País],"",0) -> Chile | B7: CIN.2 | C7: =+_xlfn.XLOOKUP(B7,Datos!A:A,Datos!C:C,"",0) -> GI | D7: 0.38 | E7: 1220 | F7: SS40/G40 | G7: 35.421815 | H7: 5-6 TM
A8: =+_xlfn.XLOOKUP(B8,Tabla22[Lote],Tabla22[País],"",0) -> Chile | B8: CIN.6 | C8: =+_xlfn.XLOOKUP(B8,Datos!A:A,Datos!C:C,"",0) -> HRC | D8: 1.82 | E8: 1200 | G8: 876 | H8: Coil: 16TM max, 13 TM min. (30%) | Coil: 18TM max, 15 TM min. (70%)
A9: =+_xlfn.XLOOKUP(B9,Tabla22[Lote],Tabla22[País],"",0) -> Chile | B9: CIN.6 | C9: =+_xlfn.XLOOKUP(B9,Datos!A:A,Datos!C:C,"",0) -> HRC | D9: 3.65 | E9: 1500 | G9: 177.6301 | H9: Coil: 22,5TM max, 19,5 TM min.
A10: =+_xlfn.XLOOKUP(B10,Tabla22[Lote],Tabla22[País],"",0) -> Chile | B10: CIN.6 | C10: =+_xlfn.XLOOKUP(B10,Datos!A:A,Datos!C:C,"",0) -> HRC | D10: 2.72 | E10: 1200 | G10: 446 | H10: Coil: 18TM max, 15 TM min.
A11: =+_xlfn.XLOOKUP(B11,Tabla22[Lote],Tabla22[País],"",0) -> Chile | B11: CIN.6 | C11: =+_xlfn.XLOOKUP(B11,Datos!A:A,Datos!C:C,"",0) -> HRC | D11: 5.65 | E11: 1500 | G11: 94.65115 | H11: Coil: 22,5TM max, 19,5 TM min.
A12: =+_xlfn.XLOOKUP(B12,Tabla22[Lote],Tabla22[País],"",0) -> Chile | B12: CIN.6 | C12: =+_xlfn.XLOOKUP(B12,Datos!A:A,Datos!C:C,"",0) -> HRC | D12: 2.74 | E12: 1200 | G12: 35.050586 | H12: Coil: 15TM max, 12 TM min.
A13: =+_xlfn.XLOOKUP(B13,Tabla22[Lote],Tabla22[País],"",0) -> Chile | B13: CIN.6D | C13: =+_xlfn.XLOOKUP(B13,Datos!A:A,Datos!C:C,"",0) -> HRC | D13: 1.35 | E13: 1200 | G13: 396 | H13: Coil: 16TM max, 13 TM min. (30%) | Coil: 18TM max, 15 TM min. (70%)
A14: =+_xlfn.XLOOKUP(B14,Tabla22[Lote],Tabla22[País],"",0) -> Chile | B14: IN.1 | C14: =+_xlfn.XLOOKUP(B14,Datos!A:A,Datos!C:C,"",0) -> ZA | D14: 0.38 | E14: 1219 | F14: AZM150 | G14: 173.68321 | H14: 5 TM
A15: =+_xlfn.XLOOKUP(B15,Tabla22[Lote],Tabla22[País],"",0) -> Chile | B15: IN.1 | C15: =+_xlfn.XLOOKUP(B15,Datos!A:A,Datos!C:C,"",0) -> ZA | D15: 0.46 | E15: 1219 | F15: AZM150 | G15: 220.01584 | H15: 5 TM
A16: =+_xlfn.XLOOKUP(B16,Tabla22[Lote],Tabla22[País],"",0) -> Chile | B16: IN.1 | C16: =+_xlfn.XLOOKUP(B16,Datos!A:A,Datos!C:C,"",0) -> ZA | D16: 0.58 | E16: 1219 | F16: AZM150 | G16: 127.95455 | H16: 5 TM
A17: =+_xlfn.XLOOKUP(B17,Tabla22[Lote],Tabla22[País],"",0) -> Chile | B17: IN.1 | C17: =+_xlfn.XLOOKUP(B17,Datos!A:A,Datos!C:C,"",0) -> ZA | D17: 0.38 | E17: 1070 | F17: AZM150 | G17: 19.010875 | H17: 5 TM
A18: =+_xlfn.XLOOKUP(B18,Tabla22[Lote],Tabla22[País],"",0) -> Chile | B18: IN.1 | C18: =+_xlfn.XLOOKUP(B18,Datos!A:A,Datos!C:C,"",0) -> ZA | D18: 0.46 | E18: 1070 | F18: AZM150 | G18: 22.836973 | H18: 5 TM
A19: =+_xlfn.XLOOKUP(B19,Tabla22[Lote],Tabla22[País],"",0) -> Chile | B19: IN.10 | C19: =+_xlfn.XLOOKUP(B19,Datos!A:A,Datos!C:C,"",0) -> GI | D19: 0.8 | E19: 1220 | F19: G90 | G19: 69.528648 | H19: 8 TM
A20: =+_xlfn.XLOOKUP(B20,Tabla22[Lote],Tabla22[País],"",0) -> Chile | B20: IN.2E | C20: =+_xlfn.XLOOKUP(B20,Datos!A:A,Datos!C:C,"",0) -> ZA | D20: 0.33 | E20: 940 | F20: AZM150 | G20: 60 | H20: 5 TM
A21: =+_xlfn.XLOOKUP(B21,Tabla22[Lote],Tabla22[País],"",0) -> Chile | B21: IN.4 | C21: =+_xlfn.XLOOKUP(B21,Datos!A:A,Datos!C:C,"",0) -> PPGL | D21: 0.46 | E21: 1219 | F21: RAL9003/7042 | G21: 375.20165 | H21: 5 TM
A22: =+_xlfn.XLOOKUP(B22,Tabla22[Lote],Tabla22[País],"",0) -> Chile | B22: IN.4 | C22: =+_xlfn.XLOOKUP(B22,Datos!A:A,Datos!C:C,"",0) -> PPGL | D22: 0.38 | E22: 1070 | F22: RAL9003/7042 | G22: 20.040605 | H22: 5 TM
A23: =+_xlfn.XLOOKUP(B23,Tabla22[Lote],Tabla22[País],"",0) -> Chile | B23: IN.4 | C23: =+_xlfn.XLOOKUP(B23,Datos!A:A,Datos!C:C,"",0) -> PPGL | D23: 0.38 | E23: 1219 | F23: TERRACOTA | G23: 201.24938 | H23: 5 TM
A24: =+_xlfn.XLOOKUP(B24,Tabla22[Lote],Tabla22[País],"",0) -> Chile | B24: IN.4 | C24: =+_xlfn.XLOOKUP(B24,Datos!A:A,Datos!C:C,"",0) -> PPGL | D24: 0.33 | E24: 950 | F24: RAL9017/7042 | G24: 8.2075282 | H24: 5 TM
A25: =+_xlfn.XLOOKUP(B25,Tabla22[Lote],Tabla22[País],"",0) -> Chile | B25: IN.4 | C25: =+_xlfn.XLOOKUP(B25,Datos!A:A,Datos!C:C,"",0) -> PPGL | D25: 0.46 | E25: 1070 | F25: RAL9003/7042 | G25: 59.333497 | H25: 5 TM
... A29: =+_xlfn.XLOOKUP(B29,Tabla22[Lote],Tabla22[País],"",0) -> Chile | B29: IN.4 | C29: =+_xlfn.XLOOKUP(B29,Datos!A:A,Datos!C:C,"",0) -> PPGL | D29: 0.46 | E29: 1219 | F29: RAL7024/7042 | G29: 68.769951 | H29: 5 TM
A30: =+_xlfn.XLOOKUP(B30,Tabla22[Lote],Tabla22[País],"",0) -> Chile | B30: IN.4 | C30: PPAM100 | D30: 0.46 | E30: 1219 | F30: RAL9003/7042 | G30: 375.20165 | H30: 5 TM
A31: =+_xlfn.XLOOKUP(B31,Tabla22[Lote],Tabla22[País],"",0) -> Chile | B31: IN.4 | C31: PPAM100 | D31: 0.38 | E31: 1070 | F31: RAL9003/7042 | G31: 20.040605 | H31: 5 TM
A32: =+_xlfn.XLOOKUP(B32,Tabla22[Lote],Tabla22[País],"",0) -> Chile | B32: IN.4 | C32: PPAM100 | D32: 0.38 | E32: 1219 | F32: TERRACOTA | G32: 201.24938 | H32: 5 TM
A33: =+_xlfn.XLOOKUP(B33,Tabla22[Lote],Tabla22[País],"",0) -> Chile | B33: IN.4 | C33: PPAM100 | D33: 0.33 | E33: 950 | F33: RAL9017/7042 | G33: 8.2075282 | H33: 5 TM
A34: =+_xlfn.XLOOKUP(B34,Tabla22[Lote],Tabla22[País],"",0) -> Chile | B34: IN.4 | C34: PPAM100 | D34: 0.46 | E34: 1070 | F34: RAL9003/7042 | G34: 59.333497 | H34: 5 TM
A35: =+_xlfn.XLOOKUP(B35,Tabla22[Lote],Tabla22[País],"",0) -> Chile | B35: IN.4 | C35: PPAM100 | D35: 0.46 | E35: 1219 | F35: RAL9006/7042 | G35: 7.7716851 | H35: 5 TM
A36: =+_xlfn.XLOOKUP(B36,Tabla22[Lote],Tabla22[País],"",0) -> Chile | B36: IN.4 | C36: PPAM100 | D36: 0.46 | E36: 1219 | F36: RAL9002/7042 | G36: 9.0441529 | H36: 5 TM
A37: =+_xlfn.XLOOKUP(B37,Tabla22[Lote],Tabla22[País],"",0) -> Chile | B37: IN.4 | C37: PPAM100 | D37: 0.46 | E37: 1219 | F37: RAL7040/7042 | G37: 24.869425 | H37: 5 TM
A38: =+_xlfn.XLOOKUP(B38,Tabla22[Lote],Tabla22[País],"",0) -> Chile | B38: IN.4 | C38: PPAM100 | D38: 0.46 | E38: 1219 | F38: RAL7024/7042 | G38: 68.769951 | H38: 5 TM
A39: =+_xlfn.XLOOKUP(B39,Tabla22[Lote],Tabla22[País],"",0) -> Chile | B39: IN.4 | C39: ZAM80 | D39: 0.46 | E39: 1219 | F39: RAL9003/7042 | G39: 375.20165 | H39: 5 TM
A40: =+_xlfn.XLOOKUP(B40,Tabla22[Lote],Tabla22[País],"",0) -> Chile | B40: IN.4 | C40: ZAM80 | D40: 0.38 | E40: 1070 | F40: RAL9003/7042 | G40: 20.040605 | H40: 5 TM
A41: =+_xlfn.XLOOKUP(B41,Tabla22[Lote],Tabla22[País],"",0) -> Chile | B41: IN.4 | C41: ZAM80 | D41: 0.38 | E41: 1219 | F41: TERRACOTA | G41: 201.24938 | H41: 5 TM
... A47: =+_xlfn.XLOOKUP(B47,Tabla22[Lote],Tabla22[País],"",0) -> Chile | B47: IN.4 | C47: ZAM80 | D47: 0.46 | E47: 1219 | F47: RAL7024/7042 | G47: 68.769951 | H47: 5 TM
A48: =+_xlfn.XLOOKUP(B48,Tabla22[Lote],Tabla22[País],"",0) -> Chile | B48: IN.7E | C48: =+_xlfn.XLOOKUP(B48,Datos!A:A,Datos!C:C,"",0) -> ZA | D48: 0.33 | E48: 940 | F48: AZM80 | G48: 90 | H48: 5 TM
...

Sheet ESPECIFICACIONES PELpara los án
C3: para los ángulos; pletinas laminadas; barras redondas lisas - estriadas (para uso estructuras metálicas), la Norma de referencia es:
C5: NCh203 Of.2006;
C6: ASTM A36 y Comercial.
C7: Calidad del acero A270ES
C8: Nota: El tema de embalaje es sumamente importante(protección para su traslado), el peso y la identificación por cada bultos(descripción del producto; numero de colada; norma de referencia de fabricación; peso del bulto).

Sheet Hoja1
B2: COUNTRY | C2: LOT | D2: STEEL | E2: TM | F2: USD/TM | G2: USD TOTAL | I2: COUNTRY | J2: LOT | K2: TM | L2: USD/TM | M2: USD TOTAL
B3: Chile | C3: CA.4 | D3: HRC | E3: 36 | F3: 563 | G3: =+F3*E3 -> 20268 | I3: Chile | J3: CA.11 | K3: 45 | L3: 628 | M3: =+L3*K3 -> 28260
C4: CA.5 | D4: CRC | E4: 150 | F4: 640 | G4: =+F4*E4 -> 96000 | J4: CIN.3PT | K4: 15.430946 | L4: 580 | M4: =+L4*K4 -> 8949.9488
C5: CA.8E | D5: HRC | E5: 165 | F5: 622 | G5: =+F5*E5 -> 102630 | J5: CIN.4PT | K5: 8.7444153 | L5: 697 | M5: =+L5*K5 -> 6094.8575
C6: CIN.2 | D6: GI | E6: 2350 | F6: 730 | G6: =+F6*E6 -> 1715500 | J6: CIN.5 PT | K6: 55.753801 | L6: 585 | M6: =+L6*K6 -> 32615.974
C7: CIN.6 | D7: HRC | E7: 495.64327 | F7: 569 | G7: =+F7*E7 -> 282021.02 | I7: Total Chile | K7: 124.92916 | M7: =+SUM(M3:M6) -> 75920.78
C8: CIN.6D | D8: HRC | E8: 300 | F8: 600 | G8: =+F8*E8 -> 180000 | I8: Perú Tupemesa | J8: TU.2 PT | K8: 5.2721356 | L8: 585 | M8: =+L8*K8 -> 3084.1993
B9: Total Chile | E9: =+SUM(E3:E8) -> 3496.6433 | G9: =+SUM(G3:G8) -> 2396419 | J9: TU.6 PT | K9: 293.14782 | L9: 680 | M9: =+L9*K9 -> 199340.52
B10: Perú Tupemesa | C10: TU.1 | D10: CRC | E10: 120 | F10: 625 | G10: =+F10*E10 -> 75000 | J10: TU.7 PT | K10: 272.5 | L10: 612 | M10: =+L10*K10 -> 166770
C11: TU.2 | D11: HRC | E11: 2911 | F11: 563 | G11: =+F11*E11 -> 1638893 | I11: Total Perú Tupemesa | K11: 570.91995 | M11: =+SUM(M8:M10) -> 369194.72
C12: TU.2D | D12: HRC | E12: 230 | F12: 589 | G12: =+F12*E12 -> 135470 | I12: Total general | K12: 695.84912 | M12: =+M11+M7 -> 445115.5
C13: TU.3 | D13: GI | E13: 722 | F13: 687 | G13: =+F13*E13 -> 496014
C14: TU.3D | D14: GI | E14: 570 | F14: 754 | G14: =+F14*E14 -> 429780
C15: TU.3E | D15: GI | E15: 100 | F15: 659 | G15: =+F15*E15 -> 65900
C16: TU.4 | D16: PPGL | E16: 25 | F16: 1044 | G16: =+F16*E16 -> 26100
B17: Total Perú Tupemesa | E17: =+SUM(E10:E16) -> 4678 | G17: =+SUM(G10:G16) -> 2867157
B18: Total general | E18: =+E17+E9 -> 8174.6433 | G18: =+G17+G9 -> 5263576
B22: COUNTRY | C22: TM
B23: Chile | C23: =+E9+K7 -> 3621.5724
B24: Perú | C24: =+E17+K11 -> 5248.92
B25: Total General | C25: =+C23+C24 -> 8870.4924
B27: COUNTRY | C27: LOT | D27: STEEL | E27: TM | F27: USD/TM | G27: USD TOTAL
B28: Chile | C28: CA.4 | D28: HRC | E28: 36 | F28: 563 | G28: =+F28*E28 -> 20268
C29: CA.5 | D29: CRC | E29: 150 | F29: 640 | G29: =+F29*E29 -> 96000
C30: CA.8E | D30: HRC | E30: 165 | F30: 622 | G30: =+F30*E30 -> 102630
C31: CIN.2 | D31: GI | E31: 2350 | F31: 730 | G31: =+F31*E31 -> 1715500
C32: CIN.6 | D32: HRC | E32: 495.64327 | F32: 569 | G32: =+F32*E32 -> 282021.02
C33: CIN.6D | D33: HRC | E33: 300 | F33: 600 | G33: =+F33*E33 -> 180000
B34: Total Chile | E34: =+SUM(E28:E33) -> 3496.6433 | G34: =+SUM(G28:G33) -> 2396419
B35: Perú Tupemesa | C35: TU.1 | D35: CRC | E35: 120 | F35: 625 | G35: =+F35*E35 -> 75000
C36: TU.3D | D36: GI | E36: 570 | F36: 754 | G36: =+F36*E36 -> 429780
C37: TU.3E | D37: GI | E37: 100 | F37: 659 | G37: =+F37*E37 -> 65900
C38: TU.4 | D38: PPGL | E38: 25 | F38: 1044 | G38: =+F38*E38 -> 26100
B39: Total Perú Tupemesa | E39: =+SUM(E35:E38) -> 815 | G39: =+SUM(G35:G38) -> 596780
B40: Total general | E40: =+E39+E34 -> 4311.6433 | G40: =+G39+G34 -> 2993199
B42: COUNTRY | C42: LOT | D42: TM | E42: USD/TM | F42: USD TOTAL
B43: Chile | C43: CA.11 | D43: 45 | E43: 628 | F43: =+E43*D43 -> 28260
C44: CIN.3PT | D44: 15.430946 | E44: 580 | F44: =+E44*D44 -> 8949.9488
C45: CIN.4PT | D45: 8.7444153 | E45: 697 | F45: =+E45*D45 -> 6094.8575
C46: CIN.5 PT | D46: 55.753801 | E46: 585 | F46: =+E46*D46 -> 32615.974
...

Sheet GENERAL SPECIFICATIONS CINTAC
A1: GENERAL SPECIFICATIONS CINTAC
A5: All products must be marked with the name "CINTAC" orange color.
A6: Mill test and packing list must be sent in Excel format. Packing List with Heat No.
A7: Offers will be accepted with observations, however they must be equivalent with the general specifications of each lot.
A8: All products must be shipped to Port Valparaíso of Chile
A11: Lot IN.1 (Instapanel) | B11: ZINCALUME (Industrial panels, roofing and siding for painting)
A13: GENERAL SPECIFICATIONS:
A14: ● Steel sheet, aluminum-zinc alloy 55%, coated in coils. Structural quality: Grade 37, according to ASTM A 792.
A15: ● Coating designation: AZM 150 Regular spangle, chromated.
A16: ● Dry. Skin passed. Leveled.
A17: Minimum surface tension: ≥ 38 dynes/cm (requirement for paint application).
A18: ● Maximum coil weight: 5 metric tons, inner coil diameter: 20".
A19: ● Properly packed for sea export with certification “Eye to the Wall”.
A20: ● SURFACE CONDITIONS: Free of oxides, stains, visible defects, inclusions, or deep marks. Finish in accordance with surface tolerances established in ASTM A 792 and specific paintability requirements.
A21: ● COILING CONDITIONS: Compact coil, without lateral displacements or deformations. Even and stable winding, without excessive telescoping or stepped layers. Edges aligned and properly contained to prevent damage during transport and handling.
A22: ● Edge waviness: ≤ 3 mm per 1000 mm (supplementary criterion), ≤ 1.5 mm for length < 200 mm (supplementary criterion).
A23: Center waviness: According to ASTM A568 / EN 10131.
A24: Camber (longitudinal bow): ≤ 5 mm over 2000 mm length (reference ASTM A568).
... A28: ● Packing list: including heat and coil number, net and gross weight, dimensions, production date, and country of origin.
A30: Thickness (1) | B30: Thickness tolerances in mm | D30: Width
A31: mm | B31: Less | C31: Over | D31: mm | E31: Used
A32: 0.33 | B32: 0.02 | C32: 0.02 | D32: 950 | E32: Industrial
A33: 0.38 | B33: 0.02 | C33: 0.02 | D33: 950 | E33: Industrial
A34: 0.38 | B34: 0.02 | C34: 0.02 | D34: 1070 | E34: Industrial
A35: 0.38 | B35: 0.02 | C35: 0.02 | D35: 1219 | E35: Industrial
A36: 0.46 | B36: 0.02 | C36: 0.02 | D36: 1219 | E36: Industrial
A37: 0.46 | B37: 0.02 | C37: 0.02 | D37: 1070 | E37: Industrial
A38: 0.58 | B38: 0.02 | C38: 0.02 | D38: 1219 | E38: Industrial
A39: 0.78 | B39: 0.02 | C39: 0.02 | D39: 1219 | E39: Industrial
A40: Subtotal
A42: Lot IN.4 (Instapanel) | B42: ZINCALUM STEEL PRE-PAINTED (Industrial panels, roofing and siding )
A44: GENERAL SPECIFICATIONS:
A45: ● Pre-painted steel with protective film. Base metal: Steel sheet coated with Al-Zn-Mg alloy by hot-dip process; G300 (equivalent to Grade 37). AS 1397:2011 – Steel sheet and strip – Hot-dipped zinc/aluminium/magnesium-coated.
A46: ● Coating designation: AM 100. Regular spangle.
A47: ● Paint type: Regular Modified Polyester (R.M.P.).
A48: ● Top side: 5 µm primer + 20 µm R.M.P. Back side: 5 µm primer. Epoxy primer, grey RAL 7042, for polyurethane injection. Hardness: 2B–2H, T-bend: TNPR 1–3, Adhesion 5B.
A49: ● Gloss: 35–40% (Width 1219 mm).
A50: ● Delta E: below 0.5.
A51: ● Maximum coil weight: 5 MT / minimum 4 MT, inner coil diameter: 20″.
A52: ● Packaging suitable for sea export. “Properly packaged for sea export – Eye to the sky.”
...

Sheet GENERAL SPECIFICATIONS TUPEMESA
A1: GENERAL SPECIFICATIONS TUPEMESA
A2: Lima Perú, August 2024
A4: ► | B4: All products must be marked with the name "TUPEMESA" orange color.
A5: ► | B5: Mill test and packing list must be sent in Excel format. Packing List with Heat No.
A6: ► | B6: Offers will be accepted with observations, however they must be equivalent with the general specifications of each lot.
A7: ► | B7: All products must be shipped to Port Callao of Perú.
A10: TU.1 (Tupemesa) | B10: Cold Rolled Sheet I colis SAE1010
A12: GENERAL SPECIFICATIONS:
A13: ● Cold Roll Sheet in coils, according to ASTM A 1008
A14: ● Thickness tolerances 50% ASTM A 568M A568 centred. Other tolerances ASTM A 568M
A15: ● Coil weight; thickness 0.6 mm 10 MT max. 10 MT min, thickness 0.73 mm 12 MT max. 10 MT min, thickness 0.78 mm 12 MT max. 10 MT min, thickness 0.85 mm 16 MT max. 12 MT min, thickness 1.12 mm 16 MT max. 12 MT min, thickness 1.4 mm 16 MT max. 12 MT min Internal diameter 610 mm max , 508 mm min.
A16: ● No fish tail, mill edges. Semi matt, oiled, supplied and, any surface defect that can affect end use.
A17: grade, size, heat, number, coil number, destination mill.
A18: ● Marking: grade, size, heat number, coil number, destination, mill.
A19: ● Packing List with Heat No.
A20: Thickness (1) | B20: Wide
A21: mm | B21: mm
A22: 0.6 | B22: 1200
A23: 0.73 | B23: 1200
A24: 0.78 | B24: 1200
A25: 0.85 | B25: 1200
A26: 1.12 | B26: 1200
A27: 1.4 | B27: 1200
A28: Subtotal
A30: Lot TU.2 (Tupemesa) | B30: Hot Roll Sheet in coils
A32: GENERAL SPECIFICATIONS:
A33: ● Hot Roll Sheet in coils, according to ASTM A 36 (Si < 0,02% and Si+ 2,5xP<0,09%)
A34: ● Tolerances: According to ASTM A568M/635M, thickness 50% ASTM A568M/635M, mean to high. Free of any surface defect, not Waved Edge( thicknesses 1.9, 2.4 and 2.90 mm )
A35: ● Coil: 23 TM max, 15 TM min.,
A36: ● Edge mill. Internal diametrer 508 mm up to 610 mm., no fish tale. Marking: grade,
B37: size, heat number, coil number, destination, mill.
A38: ● Packing List with Heat No.
A39: Thickness (1) | B39: Wide
A40: mm | B40: mm
A41: 1.88 | C41: 1190 | F41: 1200
A42: 2.38 | C42: 1200 | F42: 1200
A43: 2.85 | B43: 1200 | F43: 1200
A44: 3.3 | C44: 1200 | F44: 1200
A45: 3.5 | B45: 1200 | F45: 1200
A46: 3.85 | B46: 1100 | F46: 1100
...
